Workbook

Sheet MENU
B2: KEMENTERIAN IMIGRASI DAN PEMASYARAKATAN
B3: MENU NAVIGASI — DOKUMEN PERJALANAN DINAS
B6: SPT No: WIM.16.IMI.1-TI.04.01-2438 | Tanggal: 5 Mei 2026
B8: NAMA DOKUMEN / SHEET | D8: KETERANGAN
B9: 1 | C9: Isi Disini | D9: Form Input Data Utama
B10: 2 | C10: DPR PIC | D10: Daftar Perjalanan Dinas - PIC
B11: 3 | C11: Nominatif | D11: Daftar Nominatif Pembayaran
B12: 4 | C12: Pegawai 1 | D12: Dokumen Perjalanan Dinas No. 1
B13: 5 | C13: Pegawai 2 | D13: Dokumen Perjalanan Dinas No. 2
B14: 6 | C14: Pegawai 3 | D14: Dokumen Perjalanan Dinas No. 3
B15: 7 | C15: Pegawai 4 | D15: Dokumen Perjalanan Dinas No. 4
B16: 8 | C16: Pegawai 5 | D16: Dokumen Perjalanan Dinas No. 5
B17: 9 | C17: Pegawai 6 | D17: Dokumen Perjalanan Dinas No. 6
B18: 10 | C18: Pegawai 7 | D18: Dokumen Perjalanan Dinas No. 7
B19: 11 | C19: Pegawai 8 | D19: Dokumen Perjalanan Dinas No. 8
B20: 12 | C20: Pegawai 9 | D20: Dokumen Perjalanan Dinas No. 9
... B22: 14 | C22: DPR PIC (2) | D22: Daftar Perjalanan Dinas - PIC (Salinan)
B24: Klik nama sheet untuk berpindah halaman

Sheet Isi Disini
A1: << MENU | B1: DAFTAR NOMINATIF PEMBAYARAN PERJALANAN DINAS
B2: MELAKUKAN KEGIATAN KOORDINASI TERKAIT CONTACT CENTRE DAN PENANGANAN PENGADUAN PADA KANTOR IMIGRASI KELAS I TPI PONTIANAK KE DIREKTORAT JENDERAL IMIGRASI JAKARTA
B3: SESUAI SURAT PERINTAH TUGAS NO : | M3: WIM.16.IMI.1-TI.04.01- 2438 | P3: TANGGAL | Q3: 5 Mei 2026
C4: Pengelolaan Teknologi Informasi Keimigrasian | E4: Tanggal 6 sd 8 Mei 2026 | G4: Benar telah melaksanakan tugas perjalanan dinas berdasarkan Surat Perintah Tugas Nomor: WIM.16.IMI.1-TI.04.01-2438 Tanggal 5 Mei 2026, dalam rangka Melakukan Kegiatan Koordinasi terkait Contact Centre dan Penanganan Pengaduan pada Kantor Imigrasi Kelas I TPI Pontianak ke Direktorat Jenderal Imigrasi Jakarta;
B6: No. | C6: Nama | D6: Gol | E6: Jabatan | F6: Tujuan | G6: No SPD | H6: Tanggal SPD | I6: Tanggal Kegiatan | J6: Lama Perjalanan Dinas | M6: Biaya Perjalanan Dinas | Y6: Rekening | Z6: Tandatangan
L7: Uang Harian | M7: Tiket PP | R7: Taksi | S7: Taksi Daerah | T7: Transport antar kab/kota | U7: Uang Harian | V7: Biaya Penginapan | W7: Uang Representasi | X7: Jumlah
M8: Pergi | O8: Pulang | Q8: Jumlah
B9: 1 | C9: SYECH MUKHAMAR REZA KHARAMI, S.H. | D9: III | E9: =_xlfn.XLOOKUP(C9,'nama pegawai'!B:B,'nama pegawai'!E:E,"") -> KASI REG, ADMINISTRASI & PELAPORAN | F9: Jakarta | G9: WIM.16.IMI.1-KU.03.01-2439 | H9: 46167 | I9: 28 sd 28 Mei 2026 | J9: =IF(I9="",0,_xlfn.LET(_xlpm.teks,TRIM(I9),_xlpm.posSd,FIND(" sd ",_xlpm.teks),_xlpm.tglMulai,VALUE(LEFT(_xlpm.teks,_xlpm.posSd-1)),_xlpm.sisaKanan,TRIM(MID(_xlpm.teks,_xlpm.posSd+4,100)),_xlpm.tglSelesai,IF(ISNUMBER(VALUE(LEFT(_xlpm.sisaKanan,FIND(" ",_xlpm.sisaKanan&" ")-1))),VALUE(LEFT(_xlpm.sisaKanan,FIND(" ",_xlpm.sisaKanan&" ")-1)),VALUE(LEFT(_xlpm.sisaKanan,FIND(" ",_xlpm.sisaKanan)-1))),_xlpm.tglSelesai-_xlpm.tglMulai+1)) -> 1 | K9: =IF(J9=0,"",J9&" ("&CHOOSE(MIN(J9,31),"satu","dua","tiga","empat","lima","enam","tujuh","delapan","sembilan","sepuluh","sebelas","dua belas","tiga belas","empat belas","lima belas","enam belas","tujuh belas","delapan belas","sembilan belas","dua puluh","dua puluh satu","dua puluh dua","dua puluh tiga","dua puluh empat","dua puluh lima","dua puluh enam","dua puluh tujuh","dua puluh delapan","dua puluh sembilan","tiga puluh","tiga puluh satu")&") hari") -> 1 (satu) hari | L9: 530000 | M9: Batik Air (PNK - CGK) | N9: =6201052/4 -> 1550263 | O9: Citilink (CGK - PNK) | P9: =4445842/3 -> 1481947.3 | Q9: =N9+P9 -> 3032210.3 | R9: 250000 | S9: 96200 | U9: =J9*L9 -> 530000 | V9: =730000*2 -> 1460000 | W9: 0 | Y9: BPG 042 655216928301000
C10: =_xlfn.XLOOKUP(C9,'nama pegawai'!B:B,'nama pegawai'!C:C,"") -> 19840831 200312 1 001
B11: 2 | C11: SAULINA SIMORANGKIR, S.S. | D11: III | E11: =_xlfn.XLOOKUP(C11,'nama pegawai'!B:B,'nama pegawai'!E:E,"") -> KASUBSI REGISTRASI | F11: Jakarta | G11: WIM.16.IMI.1-KU.03.01-2440 | H11: 46169 | I11: 28 sd 28 Mei 2026 | J11: =IF(I11="",0,_xlfn.LET(_xlpm.teks,TRIM(I11),_xlpm.posSd,FIND(" sd ",_xlpm.teks),_xlpm.tglMulai,VALUE(LEFT(_xlpm.teks,_xlpm.posSd-1)),_xlpm.sisaKanan,TRIM(MID(_xlpm.teks,_xlpm.posSd+4,100)),_xlpm.tglSelesai,IF(ISNUMBER(VALUE(LEFT(_xlpm.sisaKanan,FIND(" ",_xlpm.sisaKanan&" ")-1))),VALUE(LEFT(_xlpm.sisaKanan,FIND(" ",_xlpm.sisaKanan&" ")-1)),VALUE(LEFT(_xlpm.sisaKanan,FIND(" ",_xlpm.sisaKanan)-1))),_xlpm.tglSelesai-_xlpm.tglMulai+1)) -> 1 | K11: =IF(J11=0,"",J11&" ("&CHOOSE(MIN(J11,31),"satu","dua","tiga","empat","lima","enam","tujuh","delapan","sembilan","sepuluh","sebelas","dua belas","tiga belas","empat belas","lima belas","enam belas","tujuh belas","delapan belas","sembilan belas","dua puluh","dua puluh satu","dua puluh dua","dua puluh tiga","dua puluh empat","dua puluh lima","dua puluh enam","dua puluh tujuh","dua puluh delapan","dua puluh sembilan","tiga puluh","tiga puluh satu")&") hari") -> 1 (satu) hari | L11: 530000 | M11: Batik Air (PNK - CGK) | N11: =6201052/4 -> 1550263 | O11: Citilink (CGK - PNK) | P11: =4445842/3 -> 1481947.3 | Q11: =N11+P11 -> 3032210.3 | R11: 250000 | S11: 160000 | U11: =J11*L11 -> 530000 | V11: =730000*2 -> 1460000 | W11: 0 | Y11: BPG 042 655216928301000
C12: =_xlfn.XLOOKUP(C11,'nama pegawai'!B:B,'nama pegawai'!C:C,"") -> 19800803 200912 2 001 | R12: 250000 | S12: 151500
B13: 3 | D13: II | E13: =_xlfn.XLOOKUP(C13,'nama pegawai'!B:B,'nama pegawai'!E:E,"") -> 0 | F13: Jakarta | G13: WIM.16.IMI.1-KU.03.01-2441 | H13: 46170 | I13: 28 sd 28 Mei 2026 | J13: =IF(I13="",0,_xlfn.LET(_xlpm.teks,TRIM(I13),_xlpm.posSd,FIND(" sd ",_xlpm.teks),_xlpm.tglMulai,VALUE(LEFT(_xlpm.teks,_xlpm.posSd-1)),_xlpm.sisaKanan,TRIM(MID(_xlpm.teks,_xlpm.posSd+4,100)),_xlpm.tglSelesai,IF(ISNUMBER(VALUE(LEFT(_xlpm.sisaKanan,FIND(" ",_xlpm.sisaKanan&" ")-1))),VALUE(LEFT(_xlpm.sisaKanan,FIND(" ",_xlpm.sisaKanan&" ")-1)),VALUE(LEFT(_xlpm.sisaKanan,FIND(" ",_xlpm.sisaKanan)-1))),_xlpm.tglSelesai-_xlpm.tglMulai+1)) -> 1 | K13: =IF(J13=0,"",J13&" ("&CHOOSE(MIN(J13,31),"satu","dua","tiga","empat","lima","enam","tujuh","delapan","sembilan","sepuluh","sebelas","dua belas","tiga belas","empat belas","lima belas","enam belas","tujuh belas","delapan belas","sembilan belas","dua puluh","dua puluh satu","dua puluh dua","dua puluh tiga","dua puluh empat","dua puluh lima","dua puluh enam","dua puluh tujuh","dua puluh delapan","dua puluh sembilan","tiga puluh","tiga puluh satu")&") hari") -> 1 (satu) hari | L13: 530000 | M13: Batik Air (PNK - CGK) | N13: =6201052/4 -> 1550263 | O13: Citilink (CGK - PNK) | P13: =4445842/3 -> 1481947.3 | Q13: =SUM(N13:P14) -> 3032210.3 | S13: 96000 | U13: =J13*L13 -> 530000 | V13: =730000*2 -> 1460000 | W13: 0 | X13: 1060000 | Y13: BPG 042 655216928301000
C14: =_xlfn.XLOOKUP(C13,'nama pegawai'!B:B,'nama pegawai'!C:C,"") -> 0 | S14: 150000
B15: 4 | D15: II | E15: =_xlfn.XLOOKUP(C15,'nama pegawai'!B:B,'nama pegawai'!E:E,"") -> 0 | F15: Jakarta | G15: WIM.16.IMI.1-KU.03.01-2442 | H15: 46170 | I15: 28 sd 28 Mei 2026 | J15: =IF(I15="",0,_xlfn.LET(_xlpm.teks,TRIM(I15),_xlpm.posSd,FIND(" sd ",_xlpm.teks),_xlpm.tglMulai,VALUE(LEFT(_xlpm.teks,_xlpm.posSd-1)),_xlpm.sisaKanan,TRIM(MID(_xlpm.teks,_xlpm.posSd+4,100)),_xlpm.tglSelesai,IF(ISNUMBER(VALUE(LEFT(_xlpm.sisaKanan,FIND(" ",_xlpm.sisaKanan&" ")-1))),VALUE(LEFT(_xlpm.sisaKanan,FIND(" ",_xlpm.sisaKanan&" ")-1)),VALUE(LEFT(_xlpm.sisaKanan,FIND(" ",_xlpm.sisaKanan)-1))),_xlpm.tglSelesai-_xlpm.tglMulai+1)) -> 1 | K15: =IF(J15=0,"",J15&" ("&CHOOSE(MIN(J15,31),"satu","dua","tiga","empat","lima","enam","tujuh","delapan","sembilan","sepuluh","sebelas","dua belas","tiga belas","empat belas","lima belas","enam belas","tujuh belas","delapan belas","sembilan belas","dua puluh","dua puluh satu","dua puluh dua","dua puluh tiga","dua puluh empat","dua puluh lima","dua puluh enam","dua puluh tujuh","dua puluh delapan","dua puluh sembilan","tiga puluh","tiga puluh satu")&") hari") -> 1 (satu) hari | L15: 530000 | M15: Batik Air (PNK - CGK) | N15: =6201052/4 -> 1550263 | O15: Citilink (CGK - PNK) | P15: =4445842/3 -> 1481947.3 | Q15: =SUM(N15:P16) -> 3032210.3 | R15: 219000 | S15: 150000 | T15: 0 | U15: =J15*L15 -> 530000 | V15: =730000*2 -> 1460000 | W15: 0 | X15: 1060000 | Y15: BPG 042 655216928301000
C16: =_xlfn.XLOOKUP(C15,'nama pegawai'!B:B,'nama pegawai'!C:C,"") -> 0 | S16: 151000
B17: 5 | D17: II | E17: =_xlfn.XLOOKUP(C17,'nama pegawai'!B:B,'nama pegawai'!E:E,"") -> 0 | F17: Jakarta | G17: WIM.16.IMI.1-KU.03.01-2178 | H17: 46170 | I17: 28 sd 28 Mei 2026 | J17: =IF(I17="",0,_xlfn.LET(_xlpm.teks,TRIM(I17),_xlpm.posSd,FIND(" sd ",_xlpm.teks),_xlpm.tglMulai,VALUE(LEFT(_xlpm.teks,_xlpm.posSd-1)),_xlpm.sisaKanan,TRIM(MID(_xlpm.teks,_xlpm.posSd+4,100)),_xlpm.tglSelesai,IF(ISNUMBER(VALUE(LEFT(_xlpm.sisaKanan,FIND(" ",_xlpm.sisaKanan&" ")-1))),VALUE(LEFT(_xlpm.sisaKanan,FIND(" ",_xlpm.sisaKanan&" ")-1)),VALUE(LEFT(_xlpm.sisaKanan,FIND(" ",_xlpm.sisaKanan)-1))),_xlpm.tglSelesai-_xlpm.tglMulai+1)) -> 1 | K17: =IF(J17=0,"",J17&" ("&CHOOSE(MIN(J17,31),"satu","dua","tiga","empat","lima","enam","tujuh","delapan","sembilan","sepuluh","sebelas","dua belas","tiga belas","empat belas","lima belas","enam belas","tujuh belas","delapan belas","sembilan belas","dua puluh","dua puluh satu","dua puluh dua","dua puluh tiga","dua puluh empat","dua puluh lima","dua puluh enam","dua puluh tujuh","dua puluh delapan","dua puluh sembilan","tiga puluh","tiga puluh satu")&") hari") -> 1 (satu) hari | L17: 530000 | M17: Super Air Jet (PNK - CGK) | N17: 0 | O17: Citilink (CGK - PNK) | P17: 0 | Q17: 2625600 | R17: 0 | S17: 88000 | T17: 0 | U17: =J17*L17 -> 530000 | V17: - | W17: 0 | Y17: BPG 042 655216928301000
C18: =_xlfn.XLOOKUP(C17,'nama pegawai'!B:B,'nama pegawai'!C:C,"") -> 0
B19: 6 | D19: II | E19: =_xlfn.XLOOKUP(C19,'nama pegawai'!B:B,'nama pegawai'!E:E,"") -> 0 | F19: Kubu Raya | G19: WIM.16.IMI.1-KU.03.01-1282 | H19: 46170 | I19: 25 sd 28 Mei 2026 | J19: =IF(I19="",0,_xlfn.LET(_xlpm.teks,TRIM(I19),_xlpm.posSd,FIND(" sd ",_xlpm.teks),_xlpm.tglMulai,VALUE(LEFT(_xlpm.teks,_xlpm.posSd-1)),_xlpm.sisaKanan,TRIM(MID(_xlpm.teks,_xlpm.posSd+4,100)),_xlpm.tglSelesai,IF(ISNUMBER(VALUE(LEFT(_xlpm.sisaKanan,FIND(" ",_xlpm.sisaKanan&" ")-1))),VALUE(LEFT(_xlpm.sisaKanan,FIND(" ",_xlpm.sisaKanan&" ")-1)),VALUE(LEFT(_xlpm.sisaKanan,FIND(" ",_xlpm.sisaKanan)-1))),_xlpm.tglSelesai-_xlpm.tglMulai+1)) -> 4 | K19: =IF(J19=0,"",J19&" ("&CHOOSE(MIN(J19,31),"satu","dua","tiga","empat","lima","enam","tujuh","delapan","sembilan","sepuluh","sebelas","dua belas","tiga belas","empat belas","lima belas","enam belas","tujuh belas","delapan belas","sembilan belas","dua puluh","dua puluh satu","dua puluh dua","dua puluh tiga","dua puluh empat","dua puluh lima","dua puluh enam","dua puluh tujuh","dua puluh delapan","dua puluh sembilan","tiga puluh","tiga puluh satu")&") hari") -> 4 (empat) hari | L19: 380000 | M19: - | N19: 0 | O19: - | P19: 0 | Q19: =N19+P19 -> 0 | R19: 0 | S19: 0 | T19: 0 | U19: =J19*L19 -> 1520000 | V19: - | W19: 0 | X19: 1060000 | Y19: BPG 042 655216928301000
C20: =_xlfn.XLOOKUP(C19,'nama pegawai'!B:B,'nama pegawai'!C:C,"") -> 0
B21: 7 | D21: II | E21: =_xlfn.XLOOKUP(C21,'nama pegawai'!B:B,'nama pegawai'!E:E,"") -> 0 | F21: Kubu Raya | G21: WIM.16.IMI.1-KU.03.01-1046 | H21: 46083 | I21: 28 sd 30 Mei 2026 | J21: =IF(I21="",0,_xlfn.LET(_xlpm.teks,TRIM(I21),_xlpm.posSd,FIND(" sd ",_xlpm.teks),_xlpm.tglMulai,VALUE(LEFT(_xlpm.teks,_xlpm.posSd-1)),_xlpm.sisaKanan,TRIM(MID(_xlpm.teks,_xlpm.posSd+4,100)),_xlpm.tglSelesai,IF(ISNUMBER(VALUE(LEFT(_xlpm.sisaKanan,FIND(" ",_xlpm.sisaKanan&" ")-1))),VALUE(LEFT(_xlpm.sisaKanan,FIND(" ",_xlpm.sisaKanan&" ")-1)),VALUE(LEFT(_xlpm.sisaKanan,FIND(" ",_xlpm.sisaKanan)-1))),_xlpm.tglSelesai-_xlpm.tglMulai+1)) -> 3 | K21: =IF(J21=0,"",J21&" ("&CHOOSE(MIN(J21,31),"satu","dua","tiga","empat","lima","enam","tujuh","delapan","sembilan","sepuluh","sebelas","dua belas","tiga belas","empat belas","lima belas","enam belas","tujuh belas","delapan belas","sembilan belas","dua puluh","dua puluh satu","dua puluh dua","dua puluh tiga","dua puluh empat","dua puluh lima","dua puluh enam","dua puluh tujuh","dua puluh delapan","dua puluh sembilan","tiga puluh","tiga puluh satu")&") hari") -> 3 (tiga) hari | L21: 380000 | M21: - | N21: 0 | O21: - | P21: 0 | Q21: =N21+P21 -> 0 | R21: 0 | S21: 0 | T21: 0 | U21: =J21*L21 -> 1140000 | V21: - | W21: 0 | Y21: BPG 042 655216928301000
C22: =_xlfn.XLOOKUP(C21,'nama pegawai'!B:B,'nama pegawai'!C:C,"") -> 0
B23: 8 | D23: III | E23: =_xlfn.XLOOKUP(C23,'nama pegawai'!B:B,'nama pegawai'!E:E,"") -> 0 | F23: Entikong | G23: W.16.IMI.IMI-6.KU.03.01-1638 | H23: 46170 | I23: 28 sd 28 Mei 2026 | J23: =IF(I23="",0,_xlfn.LET(_xlpm.teks,TRIM(I23),_xlpm.posSd,FIND(" sd ",_xlpm.teks),_xlpm.tglMulai,VALUE(LEFT(_xlpm.teks,_xlpm.posSd-1)),_xlpm.sisaKanan,TRIM(MID(_xlpm.teks,_xlpm.posSd+4,100)),_xlpm.tglSelesai,IF(ISNUMBER(VALUE(LEFT(_xlpm.sisaKanan,FIND(" ",_xlpm.sisaKanan&" ")-1))),VALUE(LEFT(_xlpm.sisaKanan,FIND(" ",_xlpm.sisaKanan&" ")-1)),VALUE(LEFT(_xlpm.sisaKanan,FIND(" ",_xlpm.sisaKanan)-1))),_xlpm.tglSelesai-_xlpm.tglMulai+1)) -> 1 | K23: =IF(J23=0,"",J23&" ("&CHOOSE(MIN(J23,31),"satu","dua","tiga","empat","lima","enam","tujuh","delapan","sembilan","sepuluh","sebelas","dua belas","tiga belas","empat belas","lima belas","enam belas","tujuh belas","delapan belas","sembilan belas","dua puluh","dua puluh satu","dua puluh dua","dua puluh tiga","dua puluh empat","dua puluh lima","dua puluh enam","dua puluh tujuh","dua puluh delapan","dua puluh sembilan","tiga puluh","tiga puluh satu")&") hari") -> 1 (satu) hari | L23: 0 | N23: 0 | P23: 0 | Q23: =N23+P23 -> 0 | R23: 0 | S23: 0 | T23: 0 | U23: =J23*L23 -> 0 | W23: 0 | X23: =SUM(Q23:W23) -> 0 | Y23: BPG 042 655216928301000
C24: =_xlfn.XLOOKUP(C23,'nama pegawai'!B:B,'nama pegawai'!C:C,"") -> 0
B25: 9 | D25: III | E25: =_xlfn.XLOOKUP(C25,'nama pegawai'!B:B,'nama pegawai'!E:E,"") -> 0 | F25: Entikong | G25: W.16.IMI.IMI-6.KU.03.01-1638 | H25: 46170 | I25: 28 sd 28 Mei 2026 | J25: =IF(I25="",0,_xlfn.LET(_xlpm.teks,TRIM(I25),_xlpm.posSd,FIND(" sd ",_xlpm.teks),_xlpm.tglMulai,VALUE(LEFT(_xlpm.teks,_xlpm.posSd-1)),_xlpm.sisaKanan,TRIM(MID(_xlpm.teks,_xlpm.posSd+4,100)),_xlpm.tglSelesai,IF(ISNUMBER(VALUE(LEFT(_xlpm.sisaKanan,FIND(" ",_xlpm.sisaKanan&" ")-1))),VALUE(LEFT(_xlpm.sisaKanan,FIND(" ",_xlpm.sisaKanan&" ")-1)),VALUE(LEFT(_xlpm.sisaKanan,FIND(" ",_xlpm.sisaKanan)-1))),_xlpm.tglSelesai-_xlpm.tglMulai+1)) -> 1 | K25: =IF(J25=0,"",J25&" ("&CHOOSE(MIN(J25,31),"satu","dua","tiga","empat","lima","enam","tujuh","delapan","sembilan","sepuluh","sebelas","dua belas","tiga belas","empat belas","lima belas","enam belas","tujuh belas","delapan belas","sembilan belas","dua puluh","dua puluh satu","dua puluh dua","dua puluh tiga","dua puluh empat","dua puluh lima","dua puluh enam","dua puluh tujuh","dua puluh delapan","dua puluh sembilan","tiga puluh","tiga puluh satu")&") hari") -> 1 (satu) hari | L25: 0 | N25: 0 | P25: 0 | Q25: =N25+P25 -> 0 | R25: 0 | S25: 0 | T25: 0 | U25: =J25*L25 -> 0 | V25: 0 | W25: 0 | X25: =SUM(Q25:W25) -> 0 | Y25: BPG 042 655216928301000
C26: =_xlfn.XLOOKUP(C25,'nama pegawai'!B:B,'nama pegawai'!C:C,"") -> 0
B27: 10 | D27: II | E27: =_xlfn.XLOOKUP(C27,'nama pegawai'!B:B,'nama pegawai'!E:E,"") -> 0 | F27: Entikong | G27: W.16.IMI.IMI-6.KU.03.01-1638 | H27: 46170 | I27: 28 sd 28 Mei 2026 | J27: =IF(I27="",0,_xlfn.LET(_xlpm.teks,TRIM(I27),_xlpm.posSd,FIND(" sd ",_xlpm.teks),_xlpm.tglMulai,VALUE(LEFT(_xlpm.teks,_xlpm.posSd-1)),_xlpm.sisaKanan,TRIM(MID(_xlpm.teks,_xlpm.posSd+4,100)),_xlpm.tglSelesai,IF(ISNUMBER(VALUE(LEFT(_xlpm.sisaKanan,FIND(" ",_xlpm.sisaKanan&" ")-1))),VALUE(LEFT(_xlpm.sisaKanan,FIND(" ",_xlpm.sisaKanan&" ")-1)),VALUE(LEFT(_xlpm.sisaKanan,FIND(" ",_xlpm.sisaKanan)-1))),_xlpm.tglSelesai-_xlpm.tglMulai+1)) -> 1 | K27: =IF(J27=0,"",J27&" ("&CHOOSE(MIN(J27,31),"satu","dua","tiga","empat","lima","enam","tujuh","delapan","sembilan","sepuluh","sebelas","dua belas","tiga belas","empat belas","lima belas","enam belas","tujuh belas","delapan belas","sembilan belas","dua puluh","dua puluh satu","dua puluh dua","dua puluh tiga","dua puluh empat","dua puluh lima","dua puluh enam","dua puluh tujuh","dua puluh delapan","dua puluh sembilan","tiga puluh","tiga puluh satu")&") hari") -> 1 (satu) hari | L27: 0 | N27: 0 | P27: 0 | Q27: =N27+P27 -> 0 | R27: 0 | S27: 0 | T27: 0 | U27: =J27*L27 -> 0 | V27: 0 | W27: 0 | X27: =SUM(Q27:W27) -> 0 | Y27: BPG 042 655216928301000
C28: =_xlfn.XLOOKUP(C27,'nama pegawai'!B:B,'nama pegawai'!C:C,"") -> 0
B29: 11 | D29: III | E29: =_xlfn.XLOOKUP(C29,'nama pegawai'!B:B,'nama pegawai'!E:E,"") -> 0 | F29: Entikong | G29: W.16.IMI.IMI-6.KU.03.01-1638 | H29: 46170 | I29: 28 sd 28 Mei 2026 | J29: =IF(I29="",0,_xlfn.LET(_xlpm.teks,TRIM(I29),_xlpm.posSd,FIND(" sd ",_xlpm.teks),_xlpm.tglMulai,VALUE(LEFT(_xlpm.teks,_xlpm.posSd-1)),_xlpm.sisaKanan,TRIM(MID(_xlpm.teks,_xlpm.posSd+4,100)),_xlpm.tglSelesai,IF(ISNUMBER(VALUE(LEFT(_xlpm.sisaKanan,FIND(" ",_xlpm.sisaKanan&" ")-1))),VALUE(LEFT(_xlpm.sisaKanan,FIND(" ",_xlpm.sisaKanan&" ")-1)),VALUE(LEFT(_xlpm.sisaKanan,FIND(" ",_xlpm.sisaKanan)-1))),_xlpm.tglSelesai-_xlpm.tglMulai+1)) -> 1 | K29: =IF(J29=0,"",J29&" ("&CHOOSE(MIN(J29,31),"satu","dua","tiga","empat","lima","enam","tujuh","delapan","sembilan","sepuluh","sebelas","dua belas","tiga belas","empat belas","lima belas","enam belas","tujuh belas","delapan belas","sembilan belas","dua puluh","dua puluh satu","dua puluh dua","dua puluh tiga","dua puluh empat","dua puluh lima","dua puluh enam","dua puluh tujuh","dua puluh delapan","dua puluh sembilan","tiga puluh","tiga puluh satu")&") hari") -> 1 (satu) hari | L29: 0 | N29: 0 | P29: 0 | Q29: =N29+P29 -> 0 | R29: 0 | S29: 0 | T29: 0 | U29: =J29*L29 -> 0 | V29: 0 | W29: 0 | X29: =SUM(Q29:W29) -> 0 | Y29: BPG 042 655216928301000
C30: =_xlfn.XLOOKUP(C29,'nama pegawai'!B:B,'nama pegawai'!C:C,"") -> 0
B31: 12 | D31: II | E31: =_xlfn.XLOOKUP(C31,'nama pegawai'!B:B,'nama pegawai'!E:E,"") -> 0 | F31: Entikong | G31: W.16.IMI.IMI-6.KU.03.01-1638 | H31: 46170 | I31: 28 sd 28 Mei 2026 | J31: =IF(I31="",0,_xlfn.LET(_xlpm.teks,TRIM(I31),_xlpm.posSd,FIND(" sd ",_xlpm.teks),_xlpm.tglMulai,VALUE(LEFT(_xlpm.teks,_xlpm.posSd-1)),_xlpm.sisaKanan,TRIM(MID(_xlpm.teks,_xlpm.posSd+4,100)),_xlpm.tglSelesai,IF(ISNUMBER(VALUE(LEFT(_xlpm.sisaKanan,FIND(" ",_xlpm.sisaKanan&" ")-1))),VALUE(LEFT(_xlpm.sisaKanan,FIND(" ",_xlpm.sisaKanan&" ")-1)),VALUE(LEFT(_xlpm.sisaKanan,FIND(" ",_xlpm.sisaKanan)-1))),_xlpm.tglSelesai-_xlpm.tglMulai+1)) -> 1 | K31: =IF(J31=0,"",J31&" ("&CHOOSE(MIN(J31,31),"satu","dua","tiga","empat","lima","enam","tujuh","delapan","sembilan","sepuluh","sebelas","dua belas","tiga belas","empat belas","lima belas","enam belas","tujuh belas","delapan belas","sembilan belas","dua puluh","dua puluh satu","dua puluh dua","dua puluh tiga","dua puluh empat","dua puluh lima","dua puluh enam","dua puluh tujuh","dua puluh delapan","dua puluh sembilan","tiga puluh","tiga puluh satu")&") hari") -> 1 (satu) hari | L31: 0 | N31: 0 | P31: 0 | Q31: =N31+P31 -> 0 | R31: 0 | S31: 0 | T31: 0 | U31: =J31*L31 -> 0 | V31: 0 | W31: 0 | X31: =SUM(Q31:W31) -> 0 | Y31: BPG 042 655216928301000
C32: =_xlfn.XLOOKUP(C31,'nama pegawai'!B:B,'nama pegawai'!C:C,"") -> 0
B33: 13 | D33: III | E33: =_xlfn.XLOOKUP(C33,'nama pegawai'!B:B,'nama pegawai'!E:E,"") -> 0 | F33: Entikong | G33: W.16.IMI.IMI-6.KU.03.01-1638 | H33: 46170 | I33: 28 sd 28 Mei 2026 | J33: =IF(I33="",0,_xlfn.LET(_xlpm.teks,TRIM(I33),_xlpm.posSd,FIND(" sd ",_xlpm.teks),_xlpm.tglMulai,VALUE(LEFT(_xlpm.teks,_xlpm.posSd-1)),_xlpm.sisaKanan,TRIM(MID(_xlpm.teks,_xlpm.posSd+4,100)),_xlpm.tglSelesai,IF(ISNUMBER(VALUE(LEFT(_xlpm.sisaKanan,FIND(" ",_xlpm.sisaKanan&" ")-1))),VALUE(LEFT(_xlpm.sisaKanan,FIND(" ",_xlpm.sisaKanan&" ")-1)),VALUE(LEFT(_xlpm.sisaKanan,FIND(" ",_xlpm.sisaKanan)-1))),_xlpm.tglSelesai-_xlpm.tglMulai+1)) -> 1 | K33: =IF(J33=0,"",J33&" ("&CHOOSE(MIN(J33,31),"satu","dua","tiga","empat","lima","enam","tujuh","delapan","sembilan","sepuluh","sebelas","dua belas","tiga belas","empat belas","lima belas","enam belas","tujuh belas","delapan belas","sembilan belas","dua puluh","dua puluh satu","dua puluh dua","dua puluh tiga","dua puluh empat","dua puluh lima","dua puluh enam","dua puluh tujuh","dua puluh delapan","dua puluh sembilan","tiga puluh","tiga puluh satu")&") hari") -> 1 (satu) hari | L33: 0 | N33: 0 | P33: 0 | Q33: =N33+P33 -> 0 | R33: 0 | S33: 0 | T33: 0 | U33: =J33*L33 -> 0 | V33: 0 | W33: 0 | X33: =SUM(Q33:W33) -> 0 | Y33: BPG 042 655216928301000
C34: =_xlfn.XLOOKUP(C33,'nama pegawai'!B:B,'nama pegawai'!C:C,"") -> 0
B35: TOTAL | L35: =SUM(L9:L34) -> 3410000 | M35: =SUM(Q9:Q34) -> 14754441 | R35: =SUM(R9:R34) -> 969000 | S35: =SUM(S9:S34) -> 1042700 | T35: =SUM(T9:T34) -> 0 | U35: =SUM(U9:U34) -> 5310000 | V35: =SUM(V9:V34) -> 5840000 | W35: =SUM(W33:W34) -> 0 | X35: =SUM(X9:X34) -> 3180000
W37: Pontianak,
W38: Bendahara Pengeluaran
AA43: f
W44: MUHAMMAD REZA, S.H.
W45: ="NIP. "&_xlfn.XLOOKUP(W44,'nama pegawai'!B:B,'nama pegawai'!C:C,"") -> NIP. 19840124 200212 1 002

Sheet DPR PIC
A1: << MENU | D1: KEMENTERIAN IMIGRASI DAN PEMASYARAKATAN REPUBLIK INDONESIA
D2: DIREKTORAT JENDERAL IMIGRASI
D3: KANTOR WILAYAH KALIMANTAN BARAT
D4: KANTOR IMIGRASI KELAS I TPI PONTIANAK
D5: Jalan Letjen. Sutoyo No. 122 Pontianak 78121
D6: Laman : www.pontianak.imigrasi.go.id; Surel : keuangan.kanimptk@gmail.com
B8: DAFTAR PENGELUARAN RILL
B9: OPERASI INTELIJEN DI WILAYAH
B10: PENGUMPULAN DATA DAN INFORMASI
B11: BELANJA BARANG NON OPERASIONAL LAINNYA
B12: (6161.BHB.U12.051.A.521219)
B14: Yang bertandatangan dibawah ini :
C15: NAMA | D15: : | E15: ='Isi Disini'!C9 -> SYECH MUKHAMAR REZA KHARAMI, S.H.
C16: NIP | D16: : | E16: ='Isi Disini'!C10 -> 19840831 200312 1 001
C17: JABATAN | D17: : | E17: ='Isi Disini'!E9 -> KASI REG, ADMINISTRASI & PELAPORAN
B19: Berdasarkan Surat Perintah | P19: 01 NOVEMBER 2024
C20: Tanggal | D20: : | E20: ='Isi Disini'!Q3 -> 5 Mei 2026 | P20: W.16.IMI.IMI.1-GR.01.08-4915
C21: Nomor | D21: : | E21: ='Isi Disini'!M3 -> WIM.16.IMI.1-TI.04.01- 2438
B23: dengan ini menyatakan dengan sesungguhnya bahwa:
B24: 1. | C24: Biaya belanja barang non operasional lainnya pengeluarannya, meliputi :
B26: No | C26: RINCIAN BIAYA | K26: JUMLAH | N26: KET. | R26: Biaya Uang Harian untuk 2 (dua) orang petugas selama
R27: Biaya Uang Harian untuk 4 (empat) orang petugas selama
B28: 01 | C28: Biaya Uang Harian untuk 5 (lima) orang petugas selama | K28: =D30*G30*J30 -> 7950000 | N28: =R38 -> Biaya Pengamatan/Penyusupan/ Penyurupan/Penelitian/Penjejakan | P28: Biaya Persiapan Pemeriksaan di Muara Jungkat, Kab. Mempawah | R28: Biaya Uang Harian untuk 3 (tiga) orang petugas selama
C29: 3 (tiga) hari pada | D29: ='Isi Disini'!E4 -> Tanggal 6 sd 8 Mei 2026 | R29: Biaya Uang Harian untuk 5 (lima) orang petugas selama
D30: 5 | E30: Org | F30: X | G30: 3 | H30: Hari | I30: X | J30: ='Isi Disini'!L9 -> 530000 | R30: Biaya Uang Harian untuk 6 (enam) orang petugas selama
B32: 02 | C32: Biaya Informan 1 (satu) orang | K32: Rp | M32: =D33*G33*J33 -> 1700000
D33: 1 | E33: Org | F33: x | G33: 1 | H33: Keg | I33: x | J33: 1700000 | P33: NIK SEWA RUMAH | Q33: 6171011012630007
C35: Jumlah | K35: =SUM(K27:M34) -> 9650000 | N35: {=_xlfn.LET(_xlpm.n,INT(K35),_xlpm.ratusan,_xlfn.LAMBDA(_xlpm.x,IF(_xlpm.x=0,"",IF(_xlpm.x<10,CHOOSE(_xlpm.x,"Satu","Dua","Tiga","Empat","Lima","Enam","Tujuh","Delapan","Sembilan"),IF(_xlpm.x<20,CHOOSE(_xlpm.x-9,"Sepuluh","Sebelas","Dua Belas","Tiga Belas","Empat Belas","Lima Belas","Enam Belas","Tujuh Belas","Delapan Belas","Sembilan Belas"),TRIM(IF(INT(_xlpm.x/100)>0,CHOOSE(INT(_xlpm.x/100),"Seratus","Dua Ratus","Tiga Ratus","Empat Ratus","Lima Ratus","Enam Ratus","Tujuh Ratus","Delapan Ratus","Sembilan Ratus"),"")&" "&IF(MOD(_xlpm.x,100)=0,"",IF(MOD(_xlpm.x,100)<10,CHOOSE(MOD(_xlpm.x,100),"Satu","Dua","Tiga","Empat","Lima","Enam","Tujuh","Delapan","Sembilan"),IF(MOD(_xlpm.x,100)<20,CHOOSE(MOD(_xlpm.x,100)-9,"Sepuluh","Sebelas","Dua Belas","Tiga Belas","Empat Belas","Lima Belas","Enam Belas","Tujuh Belas","Delapan Belas","Sembilan Belas"),TRIM(CHOOSE(INT(MOD(_xlpm.x,100)/10),"","Dua Puluh","Tiga Puluh","Empat Puluh","Lima Puluh","Enam Puluh","Tujuh Puluh","Delapan Puluh","Sembilan Puluh")&IF(MOD(_xlpm.x,10)>0," "&CHOOSE(MOD(_xlpm.x,10),"Satu","Dua","Tiga","Empat","Lima","Enam","Tujuh","Delapan","Sembilan"),"")))))))))),_xlpm.triliun,INT(_xlpm.n/1000000000000),_xlpm.miliar,INT(MOD(_xlpm.n,1000000000000)/1000000000),_xlpm.juta,INT(MOD(_xlpm.n,1000000000)/1000000),_xlpm.ribu,INT(MOD(_xlpm.n,1000000)/1000),_xlpm.sisa,MOD(_xlpm.n,1000),PROPER(TRIM(IF(_xlpm.triliun>0,_xlpm.ratusan(_xlpm.triliun)&" Triliun","")&" "&IF(_xlpm.miliar>0,_xlpm.ratusan(_xlpm.miliar)&" Miliar","")&" "&IF(_xlpm.juta>0,_xlpm.ratusan(_xlpm.juta)&" Juta","")&" "&IF(_xlpm.ribu>0,IF(_xlpm.ribu=1,"Seribu",_xlpm.ratusan(_xlpm.ribu)&" Ribu"),"")&" "&IF(_xlpm.sisa>0,_xlpm.ratusan(_xlpm.sisa),""))&" Rupiah"))} -> Sembilan Juta Enam Ratus Lima Puluh Ribu Rupiah | P35: Biaya Persiapan Pemeriksaan di Pelabuhan Kijing, Kabupaten Mempawah | R35: Biaya Sewa Transportasi Dalam Rangka Operasi
B37: 2. | C37: Jumlah uang tersebut pada angka 1 di atas benar-benar dikeluarkan untuk pelaksanaan kegiatan dimaksud
C38: dan apabila di kemudian hari terdapat kelebihan atas pembayaran, kami bersedia untuk menyetorkan kelebihan | R38: Biaya Pengamatan/Penyusupan/ Penyurupan/Penelitian/Penjejakan
C39: tersebut ke Kas Negara.
C41: Demikian pernyataan ini kami buat dengan sebenarnya, untuk dipergunakan sebagaimana mestinya.
K44: ='Isi Disini'!W37 -> Pontianak,
C45: Mengetahui, | K45: Penerima,
C46: PEJABAT PEMBUAT KOMITMEN | K46: =E17 -> KASI REG, ADMINISTRASI & PELAPORAN
C51: SYECH MUKHAMAR REZA KHARAMI, S.H. | K51: =E15 -> SYECH MUKHAMAR REZA KHARAMI, S.H.
C52: ="NIP. "&_xlfn.XLOOKUP(C51,'nama pegawai'!B:B,'nama pegawai'!C:C,"") -> NIP. 19840831 200312 1 001 | K52: NIP. | M52: =E16 -> 19840831 200312 1 001

Sheet Nominatif
A1: << MENU | B1: ='Isi Disini'!B1 -> DAFTAR NOMINATIF PEMBAYARAN PERJALANAN DINAS
B2: ='Isi Disini'!B2 -> MELAKUKAN KEGIATAN KOORDINASI TERKAIT CONTACT CENTRE DAN PENANGANAN PENGADUAN PADA KANTOR IMIGRASI KELAS I TPI PONTIANAK KE DIREKTORAT JENDERAL IMIGRASI JAKARTA
B3: SESUAI SURAT PERINTAH TUGAS NO : | J3: ='Isi Disini'!M3 -> WIM.16.IMI.1-TI.04.01- 2438 | M3: TANGGAL: | N3: ='Isi Disini'!Q3 -> 5 Mei 2026
B6: No. | C6: Nama | D6: Gol | E6: Jabatan | F6: Tujuan | G6: Tanggal Kegiatan | H6: Lama Perjalanan Dinas | I6: Biaya Perjalanan Dinas | S6: Rekening | T6: Tandatangan
I7: Tiket PP | L7: Taksi | M7: Taksi Daerah | N7: Transport antar kab/kota | O7: Uang Harian | P7: Biaya Penginapan | Q7: Uang Representasi | R7: Jumlah
I8: Pergi | J8: Pulang | K8: Jumlah
B9: 1 | C9: ='Isi Disini'!C9 -> SYECH MUKHAMAR REZA KHARAMI, S.H. | D9: ='Isi Disini'!D9 -> III | E9: ='Isi Disini'!E9 -> KASI REG, ADMINISTRASI & PELAPORAN | F9: ='Isi Disini'!F9 -> Jakarta | G9: ='Isi Disini'!I9 -> 28 sd 28 Mei 2026 | H9: ='Isi Disini'!K9 -> 1 (satu) hari | I9: ='Isi Disini'!N9 -> 1550263 | J9: ='Isi Disini'!P9 -> 1481947.3 | K9: =I9+J9 -> 3032210.3 | L9: =SUM('Isi Disini'!R9:R10) -> 250000 | M9: =SUM('Isi Disini'!S9:S10) -> 96200 | N9: ='Isi Disini'!T9 -> 0 | O9: ='Isi Disini'!U9 -> 530000 | P9: ='Isi Disini'!V9 -> 1460000 | Q9: ='Isi Disini'!W9 -> 0 | R9: =SUM(K9:Q9) -> 5368410.3 | S9: BPG 042 655216928301000 | T9: 1
C10: ='Isi Disini'!C10 -> 19840831 200312 1 001
B11: 2 | C11: ='Isi Disini'!C11 -> SAULINA SIMORANGKIR, S.S. | D11: ='Isi Disini'!D11 -> III | E11: ='Isi Disini'!E11 -> KASUBSI REGISTRASI | F11: ='Isi Disini'!F9 -> Jakarta | G11: ='Isi Disini'!I9 -> 28 sd 28 Mei 2026 | H11: ='Isi Disini'!K9 -> 1 (satu) hari | I11: ='Isi Disini'!N11 -> 1550263 | J11: ='Isi Disini'!P11 -> 1481947.3 | K11: ='Isi Disini'!Q11 -> 3032210.3 | L11: =SUM('Isi Disini'!R11:R12) -> 500000 | M11: =SUM('Isi Disini'!S11:S12) -> 311500 | N11: ='Isi Disini'!T9 -> 0 | O11: ='Isi Disini'!U9 -> 530000 | P11: ='Isi Disini'!V11 -> 1460000 | Q11: ='Isi Disini'!W9 -> 0 | R11: =SUM(K11:Q11) -> 5833710.3 | S11: BPG 042 655216928301000 | T11: 2
C12: ='Isi Disini'!C12 -> 19800803 200912 2 001
B13: 3 | C13: ='Isi Disini'!C13 -> 0 | D13: ='Isi Disini'!D13 -> II | E13: ='Isi Disini'!E13 -> 0 | F13: ='Isi Disini'!F11 -> Jakarta | G13: ='Isi Disini'!I11 -> 28 sd 28 Mei 2026 | H13: ='Isi Disini'!K11 -> 1 (satu) hari | I13: ='Isi Disini'!N13 -> 1550263 | J13: ='Isi Disini'!P13 -> 1481947.3 | K13: ='Isi Disini'!Q13 -> 3032210.3 | L13: =SUM('Isi Disini'!R13:R14) -> 0 | M13: =SUM('Isi Disini'!S13:S14) -> 246000 | N13: ='Isi Disini'!T11 -> 0 | O13: ='Isi Disini'!U11 -> 530000 | P13: ='Isi Disini'!V13 -> 1460000 | Q13: ='Isi Disini'!W11 -> 0 | R13: =SUM(K13:Q13) -> 5268210.3 | S13: BPG 042 655216928301000 | T13: 3
C14: ='Isi Disini'!C14 -> 0
B15: 4 | C15: ='Isi Disini'!C15 -> 0 | D15: ='Isi Disini'!D15 -> II | E15: ='Isi Disini'!E15 -> 0 | F15: ='Isi Disini'!F13 -> Jakarta | G15: ='Isi Disini'!I13 -> 28 sd 28 Mei 2026 | H15: ='Isi Disini'!K13 -> 1 (satu) hari | I15: ='Isi Disini'!N15 -> 1550263 | J15: ='Isi Disini'!P15 -> 1481947.3 | K15: ='Isi Disini'!Q15 -> 3032210.3 | L15: =SUM('Isi Disini'!R15:R16) -> 219000 | M15: =SUM('Isi Disini'!S15:S16) -> 301000 | N15: ='Isi Disini'!T13 -> 0 | O15: ='Isi Disini'!U13 -> 530000 | P15: ='Isi Disini'!V15 -> 1460000 | Q15: ='Isi Disini'!W13 -> 0 | R15: =SUM(K15:Q15) -> 5542210.3 | S15: BPG 042 655216928301000 | T15: 4
C16: ='Isi Disini'!C16 -> 0
B17: TOTAL | I17: =SUM(K9:K16) -> 12128841 | L17: =SUM(L9:L16) -> 969000 | M17: =SUM(M9:M16) -> 954700 | N17: =SUM(N9:N12) -> 0 | O17: =SUM(O9:O16) -> 2120000 | P17: =SUM(P9:P16) -> 5840000 | Q17: 0 | R17: =SUM(R9:R16) -> 22012541
D19: Mengetahui, | Q19: ='Isi Disini'!W37 -> Pontianak,
D20: Pejabat Pembuat Komitmen | Q20: Bendahara Pengeluaran
U25: f
D26: ='DPR PIC'!C51 -> SYECH MUKHAMAR REZA KHARAMI, S.H. | Q26: ='Isi Disini'!W44 -> MUHAMMAD REZA, S.H.
D27: ='DPR PIC'!C52 -> NIP. 19840831 200312 1 001 | Q27: ='Isi Disini'!W45 -> NIP. 19840124 200212 1 002

Sheet 1
A1: << MENU
K2: LAMPIRAN II PERATURAN MENTERI KEUANGAN REPUBLIK INDONESIA NOMOR 113/PMK.05/2012 TENTANG PERJALANAN DINAS JABATAN DALAM NEGERI BAGI PEJABAT NEGARA, PEGAWAI NEGERI, DAN PEGAWAI TIDAK TETAP
A4: RINCIAN BIAYA PERJALANAN DINAS
A5: Lampiran SPD Nomor | F5: : | G5: ='Isi Disini'!G9 -> WIM.16.IMI.1-KU.03.01-2439
A6: Tanggal | F6: : | G6: ='Isi Disini'!H9 -> 46167
A8: NO | B8: PERINCIAN BIAYA | K8: JUMLAH (Rp) | L8: KETERANGAN
A9: 1 | B9: ='Isi Disini'!C4 -> Pengelolaan Teknologi Informasi Keimigrasian
B10: An. | C10: =Nominatif!C9 -> SYECH MUKHAMAR REZA KHARAMI, S.H.
B11: ='Isi Disini'!E4 -> Tanggal 6 sd 8 Mei 2026
B12: Belanja Perjalanan Biasa
B13: - | C13: Tiket Pesawat | I13: =I14+I15 -> 3032210.3 | K13: =Nominatif!K9 -> 3032210.3 | N13: SBM 2.781.000
C14: ='Isi Disini'!M9 -> Batik Air (PNK - CGK) | I14: ='Isi Disini'!N9 -> 1550263 | L14: Bukti Terlampir
C15: ='Isi Disini'!O9 -> Citilink (CGK - PNK) | I15: ='Isi Disini'!P9 -> 1481947.3 | L15: Bukti Terlampir
B16: - | C16: Uang Harian | G16: ='Isi Disini'!J9 -> 1 | H16: x | I16: ='Isi Disini'!L9 -> 530000 | K16: =Nominatif!O9 -> 530000 | L16: Tidak Ada Bukti
B17: - | C17: Penginapan | K17: =Nominatif!P9 -> 1460000 | L17: Bukti Terlampir
B18: - | C18: Taksi | K18: =Nominatif!L9+Nominatif!M9 -> 346200 | L18: Bukti Terlampir
B19: - | C19: Transportasi Kegiatan Dalam Kab/Kota | K19: =Nominatif!N9 -> 0 | L19: Tidak Ada Bukti
A20: JUMLAH | K20: =SUM(K13:K19) -> 5368410.3
A21: Empat Juta Sembilan Ratus Empat Puluh Enam Ribu Empat Ratus Enam Puluh Tiga Rupiah
J23: =Nominatif!Q19 -> Pontianak,
B24: Telah Dibayar Sejumlah | J24: Telah menerima jumlah uang sebesar
B25: =K20 -> 5368410.3 | J25: =K20 -> 5368410.3
B27: Bendahara Pengeluaran | J27: Yang Menerima
B31: ='Isi Disini'!W44 -> MUHAMMAD REZA, S.H. | J31: =C10 -> SYECH MUKHAMAR REZA KHARAMI, S.H.
B32: ='Isi Disini'!W45 -> NIP. 19840124 200212 1 002 | J32: ="NIP. "&_xlfn.XLOOKUP('Isi Disini'!W44,'nama pegawai'!B:B,'nama pegawai'!C:C,"") -> NIP. 19840124 200212 1 002
A35: PERHITUNGAN SPD RAMPUNG
A37: Ditetapkan sejumlah | G37: : | H37: =K20 -> 5368410.3
A38: Yang telah dibayar sejumlah | G38: : | H38: =B25 -> 5368410.3
A39: Sisa Kurang / lebih | G39: : | H39: =H37-H38 -> 0
J42: Pejabat Pembuat Komitmen,
J47: ='Isi Disini'!W44 -> MUHAMMAD REZA, S.H.
J48: ='Isi Disini'!W45 -> NIP. 19840124 200212 1 002
A51: DAFTAR PENGELUARAN RILL
C53: Yang bertanda tangan di bawah ini :
C55: Nama | E55: : | F55: =C10 -> SYECH MUKHAMAR REZA KHARAMI, S.H.
C56: NIP | E56: : | F56: =K32 -> 0
C57: Jabatan | E57: : | F57: ='Isi Disini'!E9 -> KASI REG, ADMINISTRASI & PELAPORAN
C59: Berdasarkan Surat Perjalanan Dinas (SPD) Nomor : | J59: =G5 -> WIM.16.IMI.1-KU.03.01-2439 | M59: tanggal
C60: =G6 -> 46167 | G60: dengan ini kami menyatakan dengan sesungguhnya bahwa:
C62: 1. | D62: Biaya di bawah ini tidak dapat diperoleh bukti-bukti pengeluarannya, meliputi:
...

Sheet 2
A1: << MENU
K2: LAMPIRAN II PERATURAN MENTERI KEUANGAN REPUBLIK INDONESIA NOMOR 113/PMK.05/2012 TENTANG PERJALANAN DINAS JABATAN DALAM NEGERI BAGI PEJABAT NEGARA, PEGAWAI NEGERI, DAN PEGAWAI TIDAK TETAP
A4: RINCIAN BIAYA PERJALANAN DINAS
A5: Lampiran SPD Nomor | F5: : | G5: ='Isi Disini'!G11 -> WIM.16.IMI.1-KU.03.01-2440
A6: Tanggal | F6: : | G6: ='Isi Disini'!H11 -> 46169
A8: NO | B8: PERINCIAN BIAYA | K8: JUMLAH (Rp) | L8: KETERANGAN
A9: 1 | B9: ='Isi Disini'!C4 -> Pengelolaan Teknologi Informasi Keimigrasian
B10: An. | C10: =Nominatif!C11 -> SAULINA SIMORANGKIR, S.S.
B11: ='Isi Disini'!E4 -> Tanggal 6 sd 8 Mei 2026
B12: Belanja Perjalanan Biasa
B13: - | C13: Tiket Pesawat | K13: =Nominatif!K11 -> 3032210.3
C14: ='Isi Disini'!M11 -> Batik Air (PNK - CGK) | I14: ='Isi Disini'!N11 -> 1550263 | L14: Bukti Terlampir
C15: ='Isi Disini'!O11 -> Citilink (CGK - PNK) | I15: ='Isi Disini'!P11 -> 1481947.3 | L15: Bukti Terlampir
B16: - | C16: Uang Harian | G16: ='Isi Disini'!J11 -> 1 | H16: x | I16: ='Isi Disini'!L11 -> 530000 | K16: =G16*I16 -> 530000 | L16: Tidak Ada Bukti
B17: - | C17: Penginapan | K17: =Nominatif!P11 -> 1460000 | L17: Bukti Terlampir
B18: - | C18: Taksi | K18: =SUM(Nominatif!L11:M11) -> 811500 | L18: Bukti Terlampir
B19: - | C19: Transportasi Kegiatan Dalam Kab/Kota | K19: =Nominatif!N11 -> 0 | L19: Tidak Ada Bukti
A20: JUMLAH | K20: =SUM(K9:K19) -> 5833710.3
A21: Enam Juta Delapan Ratus Sembilan Puluh Tiga Ribu Tujuh Ratus Sepuluh Rupiah
J23: =Nominatif!Q19 -> Pontianak,
B24: Telah Dibayar Sejumlah | J24: Telah menerima jumlah uang sebesar
B25: =K20 -> 5833710.3 | J25: =K20 -> 5833710.3
B27: Bendahara Pengeluaran | J27: Yang Menerima
B31: ='Isi Disini'!W44 -> MUHAMMAD REZA, S.H. | J31: =C10 -> SAULINA SIMORANGKIR, S.S.
B32: ='Isi Disini'!W45 -> NIP. 19840124 200212 1 002 | J32: ="NIP. "&_xlfn.XLOOKUP('Isi Disini'!W44,'nama pegawai'!B:B,'nama pegawai'!C:C,"") -> NIP. 19840124 200212 1 002
A35: PERHITUNGAN SPD RAMPUNG
A37: Ditetapkan sejumlah | G37: : | H37: =K20 -> 5833710.3
A38: Yang telah dibayar sejumlah | G38: : | H38: =B25 -> 5833710.3
A39: Sisa Kurang / lebih | G39: : | H39: =H37-H38 -> 0
J42: Pejabat Pembuat Komitmen,
J47: ='Isi Disini'!W44 -> MUHAMMAD REZA, S.H.
J48: ='Isi Disini'!W45 -> NIP. 19840124 200212 1 002 | K48: 198202092000121001
A51: DAFTAR PENGELUARAN RILL
C53: Yang bertanda tangan di bawah ini :
C55: Nama | E55: : | F55: =C10 -> SAULINA SIMORANGKIR, S.S.
C56: NIP | E56: : | F56: =K32 -> 0
C57: Jabatan | E57: : | F57: ='Isi Disini'!E11 -> KASUBSI REGISTRASI
C59: Berdasarkan Surat Perjalanan Dinas (SPD) Nomor : | J59: =G5 -> WIM.16.IMI.1-KU.03.01-2440 | M59: tanggal
C60: =G6 -> 46169 | G60: dengan ini kami menyatakan dengan sesungguhnya bahwa:
C62: 1. | D62: Biaya di bawah ini tidak dapat diperoleh bukti-bukti pengeluarannya, meliputi:
...

Sheet 3
A1: << MENU
K2: LAMPIRAN II PERATURAN MENTERI KEUANGAN REPUBLIK INDONESIA NOMOR 113/PMK.05/2012 TENTANG PERJALANAN DINAS JABATAN DALAM NEGERI BAGI PEJABAT NEGARA, PEGAWAI NEGERI, DAN PEGAWAI TIDAK TETAP
A4: RINCIAN BIAYA PERJALANAN DINAS
A5: Lampiran SPD Nomor | F5: : | G5: ='Isi Disini'!G13 -> WIM.16.IMI.1-KU.03.01-2441
A6: Tanggal | F6: : | G6: ='Isi Disini'!H13 -> 46170
A8: NO | B8: PERINCIAN BIAYA | K8: JUMLAH (Rp) | L8: KETERANGAN
A9: 1 | B9: ='Isi Disini'!C4 -> Pengelolaan Teknologi Informasi Keimigrasian
B10: An. | C10: WAWAN LASMAWAN
B11: ='Isi Disini'!E4 -> Tanggal 6 sd 8 Mei 2026
B12: Belanja Perjalanan Biasa
B13: - | C13: Tiket Pesawat | K13: =Nominatif!K13 -> 3032210.3 | N13: SBM 2.781.000
C14: ='Isi Disini'!M13 -> Batik Air (PNK - CGK) | I14: ='Isi Disini'!N13 -> 1550263 | L14: Bukti Terlampir
C15: ='Isi Disini'!O13 -> Citilink (CGK - PNK) | I15: ='Isi Disini'!P13 -> 1481947.3 | L15: Bukti Terlampir
B16: - | C16: Uang Harian | G16: ='Isi Disini'!J13 -> 1 | H16: x | I16: ='Isi Disini'!L13 -> 530000 | K16: =G16*I16 -> 530000 | L16: Tidak Ada Bukti
B17: - | C17: Penginapan | K17: =Nominatif!P13 -> 1460000 | L17: Bukti Terlampir
B18: - | C18: Taksi | K18: =SUM(Nominatif!L13:M13) -> 246000 | L18: Bukti Terlampir
B19: - | C19: Transportasi Kegiatan Dalam Kab/Kota | K19: =Nominatif!N13 -> 0 | L19: Tidak Ada Bukti
A20: JUMLAH | K20: =SUM(K9:K19) -> 5268210.3
A21: Enam Juta Tiga Ratus Dua Puluh Delapan Ribu Dua Ratus Sepuluh Rupiah
J23: =Nominatif!Q19 -> Pontianak,
B24: Telah Dibayar Sejumlah | J24: Telah menerima jumlah uang sebesar
B25: =K20 -> 5268210.3 | J25: =K20 -> 5268210.3
B27: Bendahara Pengeluaran | J27: Yang Menerima
B31: SULISTYO | J31: =C10 -> WAWAN LASMAWAN
B32: NIP. | C32: 197505302001121002 | J32: ="NIP. "&_xlfn.XLOOKUP('Isi Disini'!W44,'nama pegawai'!B:B,'nama pegawai'!C:C,"") -> NIP. 19840124 200212 1 002 | K32: ='Isi Disini'!C14 -> 0
A35: PERHITUNGAN SPD RAMPUNG
A37: Ditetapkan sejumlah | G37: : | H37: =K20 -> 5268210.3
A38: Yang telah dibayar sejumlah | G38: : | H38: =B25 -> 5268210.3
A39: Sisa Kurang / lebih | G39: : | H39: =H37-H38 -> 0
J42: Pejabat Pembuat Komitmen,
J47: ='Isi Disini'!W44 -> MUHAMMAD REZA, S.H.
J48: ='Isi Disini'!W45 -> NIP. 19840124 200212 1 002 | K48: 198202092000121001
A51: DAFTAR PENGELUARAN RILL
C53: Yang bertanda tangan di bawah ini :
C55: Nama | E55: : | F55: =C10 -> WAWAN LASMAWAN
C56: NIP | E56: : | F56: =K32 -> 0
C57: Jabatan | E57: : | F57: ='Isi Disini'!E13 -> 0
C59: Berdasarkan Surat Perjalanan Dinas (SPD) Nomor : | J59: =G5 -> WIM.16.IMI.1-KU.03.01-2441 | M59: tanggal
C60: =G6 -> 46170 | G60: dengan ini kami menyatakan dengan sesungguhnya bahwa:
C62: 1. | D62: Biaya di bawah ini tidak dapat diperoleh bukti-bukti pengeluarannya, meliputi:
...

Sheet 4
A1: << MENU
K2: LAMPIRAN II PERATURAN MENTERI KEUANGAN REPUBLIK INDONESIA NOMOR 113/PMK.05/2012 TENTANG PERJALANAN DINAS JABATAN DALAM NEGERI BAGI PEJABAT NEGARA, PEGAWAI NEGERI, DAN PEGAWAI TIDAK TETAP
A4: RINCIAN BIAYA PERJALANAN DINAS
A5: Lampiran SPD Nomor | F5: : | G5: ='Isi Disini'!G15 -> WIM.16.IMI.1-KU.03.01-2442
A6: Tanggal | F6: : | G6: ='Isi Disini'!H15 -> 46170
A8: NO | B8: PERINCIAN BIAYA | K8: JUMLAH (Rp) | L8: KETERANGAN
A9: 1 | B9: ='Isi Disini'!C4 -> Pengelolaan Teknologi Informasi Keimigrasian
B10: An. | C10: =Nominatif!C15 -> 0
B11: ='Isi Disini'!E4 -> Tanggal 6 sd 8 Mei 2026
B12: Belanja Perjalanan Biasa
B13: - | C13: Tiket Pesawat | K13: =Nominatif!K15 -> 3032210.3
C14: ='Isi Disini'!M15 -> Batik Air (PNK - CGK) | I14: ='Isi Disini'!N15 -> 1550263 | L14: Bukti Terlampir
C15: ='Isi Disini'!O15 -> Citilink (CGK - PNK) | I15: ='Isi Disini'!P15 -> 1481947.3 | L15: Bukti Terlampir
B16: - | C16: Uang Harian | G16: ='Isi Disini'!J13 -> 1 | H16: x | I16: ='Isi Disini'!L15 -> 530000 | K16: =G16*I16 -> 530000 | L16: Tidak Ada Bukti
B17: - | C17: Penginapan | K17: =Nominatif!P15 -> 1460000 | L17: Bukti Terlampir
B18: - | C18: Taksi | K18: =SUM(Nominatif!L15:M15) -> 520000 | L18: Bukti Terlampir
B19: - | C19: Transportasi Kegiatan Dalam Kab/Kota | K19: =Nominatif!N15 -> 0 | L19: Tidak Ada Bukti
A20: JUMLAH | K20: =SUM(K9:K19) -> 5542210.3
A21: Enam Juta Enam Ratus Dua Ribu Dua Ratus Sepuluh Rupiah
J23: =Nominatif!Q19 -> Pontianak,
B24: Telah Dibayar Sejumlah | J24: Telah menerima jumlah uang sebesar
B25: =K20 -> 5542210.3 | J25: =K20 -> 5542210.3
B27: Bendahara Pengeluaran | J27: Yang Menerima
B31: SULISTYO | J31: =C10 -> 0
B32: NIP. | C32: 197505302001121002 | J32: ="NIP. "&_xlfn.XLOOKUP('Isi Disini'!W44,'nama pegawai'!B:B,'nama pegawai'!C:C,"") -> NIP. 19840124 200212 1 002 | K32: ='Isi Disini'!C16 -> 0
A35: PERHITUNGAN SPD RAMPUNG
A37: Ditetapkan sejumlah | G37: : | H37: =K20 -> 5542210.3
A38: Yang telah dibayar sejumlah | G38: : | H38: =B25 -> 5542210.3
A39: Sisa Kurang / lebih | G39: : | H39: =H37-H38 -> 0
J42: Pejabat Pembuat Komitmen,
J47: ='Isi Disini'!W44 -> MUHAMMAD REZA, S.H.
J48: ='Isi Disini'!W45 -> NIP. 19840124 200212 1 002
A51: DAFTAR PENGELUARAN RILL
C53: Yang bertanda tangan di bawah ini :
C55: Nama | E55: : | F55: =C10 -> 0
C56: NIP | E56: : | F56: =K32 -> 0
C57: Jabatan | E57: : | F57: ='Isi Disini'!E15 -> 0
C59: Berdasarkan Surat Perjalanan Dinas (SPD) Nomor : | J59: =G5 -> WIM.16.IMI.1-KU.03.01-2442 | M59: tanggal
C60: =G6 -> 46170 | G60: dengan ini kami menyatakan dengan sesungguhnya bahwa:
C62: 1. | D62: Biaya di bawah ini tidak dapat diperoleh bukti-bukti pengeluarannya, meliputi:
...

Sheet 5
A1: << MENU
K2: LAMPIRAN II PERATURAN MENTERI KEUANGAN REPUBLIK INDONESIA NOMOR 113/PMK.05/2012 TENTANG PERJALANAN DINAS JABATAN DALAM NEGERI BAGI PEJABAT NEGARA, PEGAWAI NEGERI, DAN PEGAWAI TIDAK TETAP
A4: RINCIAN BIAYA PERJALANAN DINAS
A5: Lampiran SPD Nomor | F5: : | G5: ='Isi Disini'!G17 -> WIM.16.IMI.1-KU.03.01-2178
A6: Tanggal | F6: : | G6: ='Isi Disini'!H17 -> 46170
A8: NO | B8: PERINCIAN BIAYA | K8: JUMLAH (Rp) | L8: KETERANGAN
A9: 1 | B9: ='Isi Disini'!C4 -> Pengelolaan Teknologi Informasi Keimigrasian
B10: An. | C10: =Nominatif!#REF! -> #REF!
B11: ='Isi Disini'!E4 -> Tanggal 6 sd 8 Mei 2026
B12: Belanja Perjalanan Biasa
B13: - | C13: Tiket Pesawat | K13: =Nominatif!#REF! -> #REF!
C14: ='Isi Disini'!M17 -> Super Air Jet (PNK - CGK) | I14: ='Isi Disini'!N17 -> 0 | L14: Bukti Terlampir
C15: ='Isi Disini'!O17 -> Citilink (CGK - PNK) | I15: ='Isi Disini'!P17 -> 0 | L15: Bukti Terlampir
B16: - | C16: Uang Harian | G16: ='Isi Disini'!J13 -> 1 | H16: x | I16: ='Isi Disini'!L17 -> 530000 | K16: =G16*I16 -> 530000 | L16: Tidak Ada Bukti
B17: - | C17: Penginapan | K17: =Nominatif!#REF! -> #REF! | L17: Tidak Ada Bukti
B18: - | C18: Taksi | K18: =Nominatif!#REF! -> #REF! | L18: Bukti Terlampir
B19: - | C19: Transportasi Kegiatan Dalam Kab/Kota | K19: =Nominatif!#REF! -> #REF! | L19: Tidak Ada Bukti
A20: JUMLAH | K20: =SUM(K9:K19) -> #REF!
A21: =PROPER([1]!terbilang(K20)&" rupiah") -> #NAME?
J23: =Nominatif!Q19 -> Pontianak,
B24: Telah Dibayar Sejumlah | J24: Telah menerima jumlah uang sebesar
B25: =K20 -> #REF! | J25: =K20 -> #REF!
B27: Bendahara Pengeluaran | J27: Yang Menerima
B31: SULISTYO | J31: =C10 -> #REF!
B32: NIP. | C32: 197505302001121002 | J32: ="NIP. "&_xlfn.XLOOKUP('Isi Disini'!W44,'nama pegawai'!B:B,'nama pegawai'!C:C,"") -> NIP. 19840124 200212 1 002 | K32: ='Isi Disini'!C18 -> 0
A35: PERHITUNGAN SPD RAMPUNG
A37: Ditetapkan sejumlah | G37: : | H37: =K20 -> #REF!
A38: Yang telah dibayar sejumlah | G38: : | H38: =B25 -> #REF!
A39: Sisa Kurang / lebih | G39: : | H39: =H37-H38 -> #REF!
J42: Pejabat Pembuat Komitmen,
J47: ='Isi Disini'!W44 -> MUHAMMAD REZA, S.H.
J48: ='Isi Disini'!W45 -> NIP. 19840124 200212 1 002 | K48: 198202092000121001
A51: DAFTAR PENGELUARAN RILL
C53: Yang bertanda tangan di bawah ini :
C55: Nama | E55: : | F55: =C10 -> #REF!
C56: NIP | E56: : | F56: =K32 -> 0
C57: Jabatan | E57: : | F57: ='Isi Disini'!E17 -> 0
C59: Berdasarkan Surat Perjalanan Dinas (SPD) Nomor : | J59: =G5 -> WIM.16.IMI.1-KU.03.01-2178 | M59: tanggal
C60: =G6 -> 46170 | G60: dengan ini kami menyatakan dengan sesungguhnya bahwa:
C62: 1. | D62: Biaya di bawah ini tidak dapat diperoleh bukti-bukti pengeluarannya, meliputi:
...

Sheet 6
A1: << MENU
K2: LAMPIRAN II PERATURAN MENTERI KEUANGAN REPUBLIK INDONESIA NOMOR 113/PMK.05/2012 TENTANG PERJALANAN DINAS JABATAN DALAM NEGERI BAGI PEJABAT NEGARA, PEGAWAI NEGERI, DAN PEGAWAI TIDAK TETAP
A4: RINCIAN BIAYA PERJALANAN DINAS
A5: Lampiran SPD Nomor | F5: : | G5: ='Isi Disini'!G19 -> WIM.16.IMI.1-KU.03.01-1282
A6: Tanggal | F6: : | G6: ='Isi Disini'!H19 -> 46170
A8: NO | B8: PERINCIAN BIAYA | K8: JUMLAH (Rp) | L8: KETERANGAN
A9: 1 | B9: ='Isi Disini'!C4 -> Pengelolaan Teknologi Informasi Keimigrasian
B10: An. | C10: =Nominatif!#REF! -> #REF!
B11: ='Isi Disini'!E4 -> Tanggal 6 sd 8 Mei 2026
B12: Belanja Perjalanan Biasa
B13: - | C13: Tiket Pesawat | K13: =I14+I15 -> 0 | N13: =K13-2781000 -> -2781000
C14: ='Isi Disini'!M19 -> - | I14: ='Isi Disini'!N19 -> 0 | L14: Tidak Ada Bukti
C15: ='Isi Disini'!O19 -> - | I15: ='Isi Disini'!P19 -> 0 | L15: Tidak Ada Bukti
B16: - | C16: Uang Harian | G16: ='Isi Disini'!J13 -> 1 | H16: x | I16: ='Isi Disini'!L19 -> 380000 | K16: =G16*I16 -> 380000 | L16: Tidak Ada Bukti
B17: - | C17: Penginapan | K17: =Nominatif!#REF! -> #REF! | L17: Tidak Ada Bukti
B18: - | C18: Taksi | K18: =Nominatif!#REF! -> #REF! | L18: Tidak Ada Bukti
B19: - | C19: Transportasi Kegiatan Dalam Kab/Kota | K19: =Nominatif!#REF! -> #REF! | L19: Tidak Ada Bukti
A20: JUMLAH | K20: =SUM(K9:K19) -> #REF!
A21: =PROPER([1]!terbilang(K20)&" rupiah") -> #NAME?
J23: =Nominatif!Q19 -> Pontianak,
B24: Telah Dibayar Sejumlah | J24: Telah menerima jumlah uang sebesar
B25: =K20 -> #REF! | J25: =K20 -> #REF!
B27: Bendahara Pengeluaran | J27: Yang Menerima
B31: SULISTYO | J31: =C10 -> #REF!
B32: NIP. | C32: 197505302001121002 | J32: ="NIP. "&_xlfn.XLOOKUP('Isi Disini'!W44,'nama pegawai'!B:B,'nama pegawai'!C:C,"") -> NIP. 19840124 200212 1 002 | K32: ='Isi Disini'!C20 -> 0
A35: PERHITUNGAN SPD RAMPUNG
A37: Ditetapkan sejumlah | G37: : | H37: =K20 -> #REF!
A38: Yang telah dibayar sejumlah | G38: : | H38: =B25 -> #REF!
A39: Sisa Kurang / lebih | G39: : | H39: =H37-H38 -> #REF!
J42: Pejabat Pembuat Komitmen,
J47: ='Isi Disini'!W44 -> MUHAMMAD REZA, S.H.
J48: ='Isi Disini'!W45 -> NIP. 19840124 200212 1 002 | K48: 198202092000121001
A51: DAFTAR PENGELUARAN RILL
C53: Yang bertanda tangan di bawah ini :
C55: Nama | E55: : | F55: =C10 -> #REF!
C56: NIP | E56: : | F56: =K32 -> 0
C57: Jabatan | E57: : | F57: ='Isi Disini'!E19 -> 0
C59: Berdasarkan Surat Perjalanan Dinas (SPD) Nomor : | J59: =G5 -> WIM.16.IMI.1-KU.03.01-1282 | M59: tanggal
C60: =G6 -> 46170 | G60: dengan ini kami menyatakan dengan sesungguhnya bahwa:
C62: 1. | D62: Biaya di bawah ini tidak dapat diperoleh bukti-bukti pengeluarannya, meliputi:
...

Sheet 7
A1: << MENU
K2: LAMPIRAN II PERATURAN MENTERI KEUANGAN REPUBLIK INDONESIA NOMOR 113/PMK.05/2012 TENTANG PERJALANAN DINAS JABATAN DALAM NEGERI BAGI PEJABAT NEGARA, PEGAWAI NEGERI, DAN PEGAWAI TIDAK TETAP
A4: RINCIAN BIAYA PERJALANAN DINAS
A5: Lampiran SPD Nomor | F5: : | G5: ='Isi Disini'!G21 -> WIM.16.IMI.1-KU.03.01-1046
A6: Tanggal | F6: : | G6: ='Isi Disini'!H21 -> 46083
A8: NO | B8: PERINCIAN BIAYA | K8: JUMLAH (Rp) | L8: KETERANGAN
A9: 1 | B9: ='Isi Disini'!C4 -> Pengelolaan Teknologi Informasi Keimigrasian
B10: An. | C10: =Nominatif!#REF! -> #REF!
B11: ='Isi Disini'!E4 -> Tanggal 6 sd 8 Mei 2026
B12: Belanja Perjalanan Biasa
B13: - | C13: Tiket Pesawat | K13: =I14+I15 -> 0
C14: ='Isi Disini'!M21 -> - | I14: ='Isi Disini'!N21 -> 0 | L14: Tidak Ada Bukti
C15: ='Isi Disini'!O21 -> - | I15: ='Isi Disini'!P21 -> 0 | L15: Tidak Ada Bukti
B16: - | C16: Uang Harian | G16: ='Isi Disini'!J13 -> 1 | H16: x | I16: ='Isi Disini'!L21 -> 380000 | K16: =G16*I16 -> 380000 | L16: Tidak Ada Bukti
B17: - | C17: Penginapan | K17: =Nominatif!#REF! -> #REF! | L17: Tidak Ada Bukti
B18: - | C18: Taksi | K18: =Nominatif!#REF! -> #REF! | L18: Tidak Ada Bukti
B19: - | C19: Transportasi Kegiatan Dalam Kab/Kota | K19: =Nominatif!#REF! -> #REF! | L19: Tidak Ada Bukti
A20: JUMLAH | K20: =SUM(K9:K19) -> #REF!
A21: =PROPER([1]!terbilang(K20)&" rupiah") -> #NAME?
J23: =Nominatif!Q19 -> Pontianak,
B24: Telah Dibayar Sejumlah | J24: Telah menerima jumlah uang sebesar
B25: =K20 -> #REF! | J25: =K20 -> #REF!
B27: Bendahara Pengeluaran | J27: Yang Menerima
B31: LISTIA MASITA | J31: =C10 -> #REF!
B32: NIP. | C32: 198705102010122001 | J32: ="NIP. "&_xlfn.XLOOKUP('Isi Disini'!W44,'nama pegawai'!B:B,'nama pegawai'!C:C,"") -> NIP. 19840124 200212 1 002 | K32: ='Isi Disini'!C22 -> 0
A35: PERHITUNGAN SPD RAMPUNG
A37: Ditetapkan sejumlah | G37: : | H37: =K20 -> #REF!
A38: Yang telah dibayar sejumlah | G38: : | H38: =B25 -> #REF!
A39: Sisa Kurang / lebih | G39: : | H39: =H37-H38 -> #REF!
J42: Pejabat Pembuat Komitmen,
J47: ='Isi Disini'!W44 -> MUHAMMAD REZA, S.H.
J48: ='Isi Disini'!W45 -> NIP. 19840124 200212 1 002 | K48: 198202092000121001
A51: DAFTAR PENGELUARAN RILL
C53: Yang bertanda tangan di bawah ini :
C55: Nama | E55: : | F55: =C10 -> #REF!
C56: NIP | E56: : | F56: =K32 -> 0
C57: Jabatan | E57: : | F57: ='Isi Disini'!E21 -> 0
C59: Berdasarkan Surat Perjalanan Dinas (SPD) Nomor : | J59: =G5 -> WIM.16.IMI.1-KU.03.01-1046 | M59: tanggal
C60: =G6 -> 46083 | G60: dengan ini kami menyatakan dengan sesungguhnya bahwa:
C62: 1. | D62: Biaya di bawah ini tidak dapat diperoleh bukti-bukti pengeluarannya, meliputi:
...

Sheet 8
A1: << MENU
K2: LAMPIRAN II PERATURAN MENTERI KEUANGAN REPUBLIK INDONESIA NOMOR 113/PMK.05/2012 TENTANG PERJALANAN DINAS JABATAN DALAM NEGERI BAGI PEJABAT NEGARA, PEGAWAI NEGERI, DAN PEGAWAI TIDAK TETAP
A4: RINCIAN BIAYA PERJALANAN DINAS
A5: Lampiran SPD Nomor | F5: : | G5: ='Isi Disini'!G23 -> W.16.IMI.IMI-6.KU.03.01-1638
A6: Tanggal | F6: : | G6: ='Isi Disini'!H23 -> 46170
A8: NO | B8: PERINCIAN BIAYA | K8: JUMLAH (Rp) | L8: KETERANGAN
A9: 1 | B9: ='Isi Disini'!C4 -> Pengelolaan Teknologi Informasi Keimigrasian
B10: An. | C10: =Nominatif!#REF! -> #REF!
B11: ='Isi Disini'!E4 -> Tanggal 6 sd 8 Mei 2026
B12: Belanja Perjalanan Biasa
B13: - | C13: Tiket Pesawat | K13: =I14+I15 -> 0
C14: ='Isi Disini'!M23 -> 0 | I14: ='Isi Disini'!N23 -> 0 | L14: Bukti Terlampir
C15: ='Isi Disini'!O23 -> 0 | I15: ='Isi Disini'!P23 -> 0 | L15: Bukti Terlampir
B16: - | C16: Uang Harian | G16: ='Isi Disini'!J13 -> 1 | H16: x | I16: ='Isi Disini'!L23 -> 0 | K16: =G16*I16 -> 0 | L16: Tidak Ada Bukti
B17: - | C17: Penginapan | K17: =Nominatif!#REF! -> #REF! | L17: Tidak Ada Bukti
B18: - | C18: Taksi | K18: =Nominatif!#REF!+Nominatif!#REF! -> #REF! | L18: Bukti Terlampir
B19: - | C19: Transportasi Kegiatan Dalam Kab/Kota | K19: =Nominatif!#REF! -> #REF! | L19: Tidak Ada Bukti
A20: JUMLAH | K20: =SUM(K9:K19) -> #REF!
A21: =PROPER([3]!terbilang(K20)&" rupiah") -> #NAME?
J23: =Nominatif!Q19 -> Pontianak,
B24: Telah Dibayar Sejumlah | J24: Telah menerima jumlah uang sebesar
B25: =K20 -> #REF! | J25: =K20 -> #REF!
B27: Bendahara Pengeluaran | J27: Yang Menerima
B31: HARDIAN RAMADHANA S | J31: =C10 -> #REF!
B32: NIP. | C32: 198804252012121000 | J32: ="NIP. "&_xlfn.XLOOKUP('Isi Disini'!W44,'nama pegawai'!B:B,'nama pegawai'!C:C,"") -> NIP. 19840124 200212 1 002 | K32: ='Isi Disini'!C24 -> 0
A35: PERHITUNGAN SPD RAMPUNG
A37: Ditetapkan sejumlah | G37: : | H37: =K20 -> #REF!
A38: Yang telah dibayar sejumlah | G38: : | H38: =B25 -> #REF!
A39: Sisa Kurang / lebih | G39: : | H39: =H37-H38 -> #REF!
J42: Pejabat Pembuat Komitmen,
J47: ='Isi Disini'!W44 -> MUHAMMAD REZA, S.H.
J48: ='Isi Disini'!W45 -> NIP. 19840124 200212 1 002 | K48: 196710221992031001
A51: DAFTAR PENGELUARAN RILL
C53: Yang bertanda tangan di bawah ini :
C55: Nama | E55: : | F55: =C10 -> #REF!
C56: NIP | E56: : | F56: =K32 -> 0
C57: Jabatan | E57: : | F57: ='Isi Disini'!E23 -> 0
C59: Berdasarkan Surat Perjalanan Dinas (SPD) Nomor : | J59: =G5 -> W.16.IMI.IMI-6.KU.03.01-1638 | M59: tanggal
C60: =G6 -> 46170 | G60: dengan ini kami menyatakan dengan sesungguhnya bahwa:
C62: 1. | D62: Biaya di bawah ini tidak dapat diperoleh bukti-bukti pengeluarannya, meliputi:
...

Sheet 9
A1: << MENU
K2: LAMPIRAN II PERATURAN MENTERI KEUANGAN REPUBLIK INDONESIA NOMOR 113/PMK.05/2012 TENTANG PERJALANAN DINAS JABATAN DALAM NEGERI BAGI PEJABAT NEGARA, PEGAWAI NEGERI, DAN PEGAWAI TIDAK TETAP
A4: RINCIAN BIAYA PERJALANAN DINAS
A5: Lampiran SPD Nomor | F5: : | G5: ='Isi Disini'!G25 -> W.16.IMI.IMI-6.KU.03.01-1638
A6: Tanggal | F6: : | G6: ='Isi Disini'!H25 -> 46170
A8: NO | B8: PERINCIAN BIAYA | K8: JUMLAH (Rp) | L8: KETERANGAN
A9: 1 | B9: ='Isi Disini'!C4 -> Pengelolaan Teknologi Informasi Keimigrasian
B10: An. | C10: =Nominatif!#REF! -> #REF!
B11: ='Isi Disini'!E4 -> Tanggal 6 sd 8 Mei 2026
B12: Belanja Perjalanan Biasa
B13: - | C13: Tiket Pesawat | K13: =I14+I15 -> 0
C14: ='Isi Disini'!M25 -> 0 | I14: ='Isi Disini'!N25 -> 0 | L14: Bukti Terlampir
C15: ='Isi Disini'!O25 -> 0 | I15: ='Isi Disini'!P25 -> 0 | L15: Bukti Terlampir
B16: - | C16: Uang Harian | G16: ='Isi Disini'!J13 -> 1 | H16: x | I16: ='Isi Disini'!L25 -> 0 | K16: =G16*I16 -> 0 | L16: Tidak Ada Bukti
B17: - | C17: Penginapan | K17: =Nominatif!#REF! -> #REF! | L17: Tidak Ada Bukti
B18: - | C18: Taksi | K18: =Nominatif!#REF!+Nominatif!#REF! -> #REF! | L18: Bukti Terlampir
B19: - | C19: Transportasi Kegiatan Dalam Kab/Kota | K19: =Nominatif!#REF! -> #REF! | L19: Tidak Ada Bukti
A20: JUMLAH | K20: =SUM(K9:K19) -> #REF!
A21: =PROPER([3]!terbilang(K20)&" rupiah") -> #NAME?
J23: =Nominatif!Q19 -> Pontianak,
B24: Telah Dibayar Sejumlah | J24: Telah menerima jumlah uang sebesar
B25: =K20 -> #REF! | J25: =K20 -> #REF!
B27: Bendahara Pengeluaran | J27: Yang Menerima
B31: HARDIAN RAMADHANA S | J31: =C10 -> #REF!
B32: NIP. | C32: 198804252012121000 | J32: ="NIP. "&_xlfn.XLOOKUP('Isi Disini'!W44,'nama pegawai'!B:B,'nama pegawai'!C:C,"") -> NIP. 19840124 200212 1 002 | K32: ='Isi Disini'!C26 -> 0
A35: PERHITUNGAN SPD RAMPUNG
A37: Ditetapkan sejumlah | G37: : | H37: =K20 -> #REF!
A38: Yang telah dibayar sejumlah | G38: : | H38: =B25 -> #REF!
A39: Sisa Kurang / lebih | G39: : | H39: =H37-H38 -> #REF!
J42: Pejabat Pembuat Komitmen,
J47: ='Isi Disini'!W44 -> MUHAMMAD REZA, S.H.
J48: ='Isi Disini'!W45 -> NIP. 19840124 200212 1 002 | K48: 196710221992031001
A51: DAFTAR PENGELUARAN RILL
C53: Yang bertanda tangan di bawah ini :
C55: Nama | E55: : | F55: =C10 -> #REF!
C56: NIP | E56: : | F56: =K32 -> 0
C57: Jabatan | E57: : | F57: ='Isi Disini'!E25 -> 0
C59: Berdasarkan Surat Perjalanan Dinas (SPD) Nomor : | J59: =G5 -> W.16.IMI.IMI-6.KU.03.01-1638 | M59: tanggal
C60: =G6 -> 46170 | G60: dengan ini kami menyatakan dengan sesungguhnya bahwa:
C62: 1. | D62: Biaya di bawah ini tidak dapat diperoleh bukti-bukti pengeluarannya, meliputi:
...

Sheet 10
A1: << MENU
K2: LAMPIRAN II PERATURAN MENTERI KEUANGAN REPUBLIK INDONESIA NOMOR 113/PMK.05/2012 TENTANG PERJALANAN DINAS JABATAN DALAM NEGERI BAGI PEJABAT NEGARA, PEGAWAI NEGERI, DAN PEGAWAI TIDAK TETAP
A4: RINCIAN BIAYA PERJALANAN DINAS
A5: Lampiran SPD Nomor | F5: : | G5: ='Isi Disini'!G27 -> W.16.IMI.IMI-6.KU.03.01-1638
A6: Tanggal | F6: : | G6: ='Isi Disini'!H27 -> 46170
A8: NO | B8: PERINCIAN BIAYA | K8: JUMLAH (Rp) | L8: KETERANGAN
A9: 1 | B9: ='Isi Disini'!C4 -> Pengelolaan Teknologi Informasi Keimigrasian
B10: An. | C10: =Nominatif!#REF! -> #REF!
B11: ='Isi Disini'!E4 -> Tanggal 6 sd 8 Mei 2026
B12: Belanja Perjalanan Biasa
B13: - | C13: Tiket Pesawat | K13: =I14+I15 -> 0
C14: ='Isi Disini'!M27 -> 0 | I14: ='Isi Disini'!N27 -> 0 | L14: Bukti Terlampir
C15: ='Isi Disini'!O27 -> 0 | I15: ='Isi Disini'!P27 -> 0 | L15: Bukti Terlampir
B16: - | C16: Uang Harian | G16: ='Isi Disini'!J13 -> 1 | H16: x | I16: ='Isi Disini'!L27 -> 0 | K16: =G16*I16 -> 0 | L16: Tidak Ada Bukti
B17: - | C17: Penginapan | K17: =Nominatif!#REF! -> #REF! | L17: Tidak Ada Bukti
B18: - | C18: Taksi | K18: =Nominatif!#REF!+Nominatif!#REF! -> #REF! | L18: Bukti Terlampir
B19: - | C19: Transportasi Kegiatan Dalam Kab/Kota | K19: =Nominatif!#REF! -> #REF! | L19: Tidak Ada Bukti
A20: JUMLAH | K20: =SUM(K9:K19) -> #REF!
A21: =PROPER([3]!terbilang(K20)&" rupiah") -> #NAME?
J23: =Nominatif!Q19 -> Pontianak,
B24: Telah Dibayar Sejumlah | J24: Telah menerima jumlah uang sebesar
B25: =K20 -> #REF! | J25: =K20 -> #REF!
B27: Bendahara Pengeluaran | J27: Yang Menerima
B31: HARDIAN RAMADHANA S | J31: =C10 -> #REF!
B32: NIP. | C32: 198804252012121000 | J32: ="NIP. "&_xlfn.XLOOKUP('Isi Disini'!W44,'nama pegawai'!B:B,'nama pegawai'!C:C,"") -> NIP. 19840124 200212 1 002 | K32: ='Isi Disini'!C28 -> 0
A35: PERHITUNGAN SPD RAMPUNG
A37: Ditetapkan sejumlah | G37: : | H37: =K20 -> #REF!
A38: Yang telah dibayar sejumlah | G38: : | H38: =B25 -> #REF!
A39: Sisa Kurang / lebih | G39: : | H39: =H37-H38 -> #REF!
J42: Pejabat Pembuat Komitmen,
J47: ='Isi Disini'!W44 -> MUHAMMAD REZA, S.H.
J48: ='Isi Disini'!W45 -> NIP. 19840124 200212 1 002 | K48: 196710221992031001
A51: DAFTAR PENGELUARAN RILL
C53: Yang bertanda tangan di bawah ini :
C55: Nama | E55: : | F55: =C10 -> #REF!
C56: NIP | E56: : | F56: =K32 -> 0
C57: Jabatan | E57: : | F57: ='Isi Disini'!E27 -> 0
C59: Berdasarkan Surat Perjalanan Dinas (SPD) Nomor : | J59: =G5 -> W.16.IMI.IMI-6.KU.03.01-1638 | M59: tanggal
C60: =G6 -> 46170 | G60: dengan ini kami menyatakan dengan sesungguhnya bahwa:
C62: 1. | D62: Biaya di bawah ini tidak dapat diperoleh bukti-bukti pengeluarannya, meliputi:
...

Sheet DPR PIC (2)
A1: << MENU | C1: KEMENTERIAN IMIGRASI DAN PEMASYARAKATAN REPUBLIK INDONESIA
C2: DIREKTORAT JENDERAL IMIGRASI
C3: KANTOR WILAYAH KALIMANTAN BARAT
C4: KANTOR IMIGRASI KELAS I TPI PONTIANAK
C5: Jalan Letjen. Sutoyo No. 122 Pontianak 78121
C6: Laman : www.pontianak.imigrasi.go.id; Surel : keuangan.kanimptk@gmail.com
A8: DAFTAR PENGELUARAN RILL
A9: OPERASI INTELIJEN DI WILAYAH
A10: PENGUMPULAN DATA DAN INFORMASI
A11: BELANJA SEWA
A12: (6161.BHB.U12.051.A.522141)
A14: Yang bertandatangan dibawah ini :
B15: NAMA | C15: : | D15: ='Isi Disini'!C9 -> SYECH MUKHAMAR REZA KHARAMI, S.H.
B16: NIP | C16: : | D16: ='Isi Disini'!C10 -> 19840831 200312 1 001
B17: JABATAN | C17: : | D17: ='Isi Disini'!E9 -> KASI REG, ADMINISTRASI & PELAPORAN
A19: Berdasarkan Surat Perintah | O19: 01 NOVEMBER 2024
B20: Tanggal | C20: : | D20: ='Isi Disini'!Q3 -> 5 Mei 2026 | O20: W.16.IMI.IMI.1-GR.01.08-4915
B21: Nomor | C21: : | D21: ='Isi Disini'!M3 -> WIM.16.IMI.1-TI.04.01- 2438
A23: dengan ini menyatakan dengan sesungguhnya bahwa:
A24: 1. | B24: Biaya belanja sewa pengeluarannya, meliputi : | O24: NIK SEWA RUMAH | P24: 6171011012630007
A26: No | B26: RINCIAN BIAYA | J26: JUMLAH | M26: KET. | Q26: Biaya Uang Harian untuk 2 (dua) orang petugas selama
Q27: Biaya Uang Harian untuk 4 (empat) orang petugas selama
A28: 01 | B28: Biaya sewa Safehouse 1 (satu) unit selama | J28: =C30*F30*I30 -> 3000000 | M28: =Q35 -> Biaya Pengamatan/Penyusupan/ Penyurupan/Penelitian/Penjejakan | O28: Biaya Persiapan Pemeriksaan di Muara Jungkat, Kab. Mempawah | Q28: Biaya Uang Harian untuk 3 (tiga) orang petugas selama
B29: 3 (tiga) hari pada | C29: ='Isi Disini'!E4 -> Tanggal 6 sd 8 Mei 2026 | Q29: Biaya Uang Harian untuk 5 (lima) orang petugas selama
C30: 1 | D30: unit | E30: X | F30: 1 | G30: Keg | H30: X | I30: 3000000 | Q30: Biaya Uang Harian untuk 6 (enam) orang petugas selama
B32: Jumlah | J32: =SUM(J27:L31) -> 3000000 | M32: =PROPER([1]!terbilang(J32)&" rupiah") -> #NAME? | O32: Biaya Persiapan Pemeriksaan di Pelabuhan Kijing, Kabupaten Mempawah | Q32: Biaya Sewa Transportasi Dalam Rangka Operasi
A34: 2. | B34: Jumlah uang tersebut pada angka 1 di atas benar-benar dikeluarkan untuk pelaksanaan kegiatan dimaksud
B35: dan apabila di kemudian hari terdapat kelebihan atas pembayaran, kami bersedia untuk menyetorkan kelebihan | Q35: Biaya Pengamatan/Penyusupan/ Penyurupan/Penelitian/Penjejakan
B36: tersebut ke Kas Negara.
B38: Demikian pernyataan ini kami buat dengan sebenarnya, untuk dipergunakan sebagaimana mestinya.
J41: ='Isi Disini'!W37 -> Pontianak,
B42: Mengetahui, | J42: Penerima,
B43: PEJABAT PEMBUAT KOMITMEN | J43: =D17 -> KASI REG, ADMINISTRASI & PELAPORAN
J47: ='Isi Disini'!W44 -> MUHAMMAD REZA, S.H.
B48: SAM FERNANDO | J48: ='Isi Disini'!W45 -> NIP. 19840124 200212 1 002
B49: NIP. 198202092000121001 | J49: NIP. | L49: =D16 -> 19840831 200312 1 001

Sheet nama pegawai
A1: 1 | B1: MOKHAMAD REZA SULAEMAN, A.Md.Im., S.IP. | C1: 19800921 200112 1 001 | D1: PENATA TK. I / (III/d) | E1: PLT. KEPALA RUDENIM PONTIANAK
